<sdf version='1.6'>
  <world name='default'>
    <model name='ground_plane'>
      <static>1</static>
      <link name='link'>
        <collision name='collision'>
          <geometry>
            <plane>
              <normal>0 0 1</normal>
              <size>100 100</size>
            </plane>
          </geometry>
          <surface>
            <contact>
              <collide_bitmask>65535</collide_bitmask>
              <ode/>
            </contact>
            <friction>
              <ode>
                <mu>100</mu>
                <mu2>50</mu2>
              </ode>
              <torsional>
                <ode/>
              </torsional>
            </friction>
            <bounce/>
          </surface>
          <max_contacts>10</max_contacts>
        </collision>
        <visual name='visual'>
          <cast_shadows>0</cast_shadows>
          <geometry>
            <plane>
              <normal>0 0 1</normal>
              <size>100 100</size>
            </plane>
          </geometry>
          <material>
            <script>
              <uri>file://media/materials/scripts/gazebo.material</uri>
              <name>Gazebo/Grey</name>
            </script>
          </material>
        </visual>
        <self_collide>0</self_collide>
        <enable_wind>0</enable_wind>
        <kinematic>0</kinematic>
      </link>
    </model>
    <light name='sun' type='directional'>
      <cast_shadows>1</cast_shadows>
      <pose frame=''>0 0 10 0 -0 0</pose>
      <diffuse>0.8 0.8 0.8 1</diffuse>
      <specular>0.2 0.2 0.2 1</specular>
      <attenuation>
        <range>1000</range>
        <constant>0.9</constant>
        <linear>0.01</linear>
        <quadratic>0.001</quadratic>
      </attenuation>
      <direction>-0.5 0.1 -0.9</direction>
    </light>
    <model name='coke_min'>
      <link name='link'>
        <inertial>
          <pose frame=''>0 0 0.06 0 -0 0</pose>
          <mass>0.39</mass>
          <inertia>
            <ixx>0.00055575</ixx>
            <ixy>0</ixy>
            <ixz>0</ixz>
            <iyy>0.00055575</iyy>
            <iyz>0</iyz>
            <izz>0.0001755</izz>
          </inertia>
        </inertial>
        <self_collide>0</self_collide>
        <enable_wind>0</enable_wind>
        <kinematic>0</kinematic>
        <pose frame=''>0 0 0 0 -0 0</pose>
        <gravity>1</gravity>
        <visual name='visual'>
          <pose frame=''>0.003937 0.004724 -0.18 0 -0 0</pose>
          <geometry>
            <mesh>
              <uri>model://coke_can/meshes/coke_can.dae</uri>
              <scale>0.6 0.6 1</scale>
            </mesh>
          </geometry>
          <transparency>0</transparency>
          <cast_shadows>1</cast_shadows>
          <material>
            <shader type='vertex'>
              <normal_map>__default__</normal_map>
            </shader>
            <script>
              <name>ModelPreview_1::link::visual_MATERIAL_</name>
              <uri>__default__</uri>
            </script>
            <ambient>0 0 0 1</ambient>
            <diffuse>0 0 0 1</diffuse>
            <specular>0 0 0 1</specular>
            <emissive>0 0 0 1</emissive>
          </material>
        </visual>
        <collision name='collision'>
          <laser_retro>0</laser_retro>
          <max_contacts>10</max_contacts>
          <pose frame=''>0.003937 0.004724 -0.18 0 -0 0</pose>
          <geometry>
            <mesh>
              <uri>/home/charles/.gazebo/models/coke_can/meshes/coke_can.dae</uri>
              <scale>0.6 0.6 1</scale>
            </mesh>
          </geometry>
          <surface>
            <friction>
              <ode>
                <mu>1</mu>
                <mu2>1</mu2>
                <fdir1>0 0 0</fdir1>
                <slip1>0</slip1>
                <slip2>0</slip2>
              </ode>
              <torsional>
                <coefficient>1</coefficient>
                <patch_radius>0</patch_radius>
                <surface_radius>0</surface_radius>
                <use_patch_radius>1</use_patch_radius>
                <ode>
                  <slip>0</slip>
                </ode>
              </torsional>
            </friction>
            <bounce>
              <restitution_coefficient>0</restitution_coefficient>
              <threshold>1e+06</threshold>
            </bounce>
            <contact>
              <collide_without_contact>0</collide_without_contact>
              <collide_without_contact_bitmask>1</collide_without_contact_bitmask>
              <collide_bitmask>1</collide_bitmask>
              <ode>
                <soft_cfm>0</soft_cfm>
                <soft_erp>0.2</soft_erp>
                <kp>1e+07</kp>
                <kd>1</kd>
                <max_vel>0.1</max_vel>
                <min_depth>0.001</min_depth>
              </ode>
              <bullet>
                <split_impulse>1</split_impulse>
                <split_impulse_penetration_threshold>-0.01</split_impulse_penetration_threshold>
                <soft_cfm>0</soft_cfm>
                <soft_erp>0.2</soft_erp>
                <kp>1e+07</kp>
                <kd>1</kd>
              </bullet>
            </contact>
          </surface>
        </collision>
      </link>
      <static>0</static>
      <allow_auto_disable>1</allow_auto_disable>
      <pose frame=''>0.509866 0.298982 0.09203 0 -0 0</pose>
    </model>
    <model name='unit_box'>
      <pose frame=''>0.35 0 0 0 -0 0</pose>
      <link name='link'>
        <inertial>
          <mass>1</mass>
          <inertia>
            <ixx>0.166667</ixx>
            <ixy>0</ixy>
            <ixz>0</ixz>
            <iyy>0.166667</iyy>
            <iyz>0</iyz>
            <izz>0.166667</izz>
          </inertia>
        </inertial>
        <collision name='collision'>
          <geometry>
            <box>
              <size>1 1 0.05</size>
            </box>
          </geometry>
          <max_contacts>10</max_contacts>
          <surface>
            <contact>
              <ode/>
            </contact>
            <bounce/>
            <friction>
              <torsional>
                <ode/>
              </torsional>
              <ode/>
            </friction>
          </surface>
        </collision>
        <visual name='visual'>
          <geometry>
            <box>
              <size>1 1 0.075</size>
            </box>
          </geometry>
          <material>
            <script>
              <name>Gazebo/Grey</name>
              <uri>file://media/materials/scripts/gazebo.material</uri>
            </script>
          </material>
        </visual>
        <self_collide>0</self_collide>
        <enable_wind>0</enable_wind>
        <kinematic>0</kinematic>
      </link>
    </model>
    <gravity>0 0 -9.8</gravity>
    <magnetic_field>6e-06 2.3e-05 -4.2e-05</magnetic_field>
    <atmosphere type='adiabatic'/>
    <physics name='default_physics' default='0' type='ode'>
      <max_step_size>0.001</max_step_size>
      <real_time_factor>1</real_time_factor>
      <real_time_update_rate>1000</real_time_update_rate>
    </physics>
    <scene>
      <ambient>0.4 0.4 0.4 1</ambient>
      <background>0.7 0.7 0.7 1</background>
      <shadows>1</shadows>
    </scene>
    <audio>
      <device>default</device>
    </audio>
    <wind/>
    <spherical_coordinates>
      <surface_model>EARTH_WGS84</surface_model>
      <latitude_deg>0</latitude_deg>
      <longitude_deg>0</longitude_deg>
      <elevation>0</elevation>
      <heading_deg>0</heading_deg>
    </spherical_coordinates>
    <model name='yumi'>
      <link name='yumi_base_link'>
        <pose frame=''>0 0 0.1 0 -0 0</pose>
        <inertial>
          <pose frame=''>0 0 0 0 -0 0</pose>
          <mass>15</mass>
          <inertia>
            <ixx>0.5</ixx>
            <ixy>0</ixy>
            <ixz>0</ixz>
            <iyy>0.6</iyy>
            <iyz>0</iyz>
            <izz>0.3</izz>
          </inertia>
        </inertial>
        <collision name='yumi_base_link_fixed_joint_lump__yumi_body_collision'>
          <pose frame=''>0 0 0 0 -0 0</pose>
          <geometry>
            <mesh>
              <scale>1 1 1</scale>
              <uri>/home/charles/yumi_depends_ws/src/yumi/yumi_description/meshes/coarse/body.stl</uri>
            </mesh>
          </geometry>
          <surface>
            <contact>
              <ode/>
            </contact>
            <friction>
              <ode>
                <mu>0.2</mu>
                <mu2>0.2</mu2>
              </ode>
              <torsional>
                <ode/>
              </torsional>
            </friction>
            <bounce/>
          </surface>
          <max_contacts>10</max_contacts>
        </collision>
        <visual name='yumi_base_link_fixed_joint_lump__yumi_body_visual'>
          <pose frame=''>0 0 0 0 -0 0</pose>
          <geometry>
            <mesh>
              <scale>1 1 1</scale>
              <uri>/home/charles/yumi_depends_ws/src/yumi/yumi_description/meshes/body.stl</uri>
            </mesh>
          </geometry>
          <material>
            <script>
              <name>Gazebo/Ivory</name>
              <uri>file://media/materials/scripts/gazebo.material</uri>
            </script>
          </material>
        </visual>
        <gravity>1</gravity>
        <velocity_decay/>
        <self_collide>0</self_collide>
        <enable_wind>0</enable_wind>
        <kinematic>0</kinematic>
      </link>
      <joint name='world_joint' type='fixed'>
        <child>yumi_base_link</child>
        <parent>world</parent>
      </joint>
      <link name='yumi_link_1_l'>
        <pose frame=''>0.05355 0.0725 0.51492 0.9781 -0.5716 2.318</pose>
        <inertial>
          <pose frame=''>0 -0.03 0.12 0 -0 0</pose>
          <mass>2</mass>
          <inertia>
            <ixx>0.1</ixx>
            <ixy>0</ixy>
            <ixz>0</ixz>
            <iyy>0.1</iyy>
            <iyz>0</iyz>
            <izz>0.1</izz>
          </inertia>
        </inertial>
        <collision name='yumi_link_1_l_collision'>
          <pose frame=''>0 0 0 0 -0 0</pose>
          <geometry>
            <mesh>
              <scale>1 1 1</scale>
              <uri>/home/charles/yumi_depends_ws/src/yumi/yumi_description/meshes/coarse/link_1.stl</uri>
            </mesh>
          </geometry>
          <max_contacts>10</max_contacts>
          <surface>
            <contact>
              <ode/>
            </contact>
            <bounce/>
            <friction>
              <torsional>
                <ode/>
              </torsional>
              <ode/>
            </friction>
          </surface>
        </collision>
        <visual name='yumi_link_1_l_visual'>
          <pose frame=''>0 0 0 0 -0 0</pose>
          <geometry>
            <mesh>
              <scale>1 1 1</scale>
              <uri>/home/charles/yumi_depends_ws/src/yumi/yumi_description/meshes/link_1.stl</uri>
            </mesh>
          </geometry>
        </visual>
        <self_collide>0</self_collide>
        <enable_wind>0</enable_wind>
        <kinematic>0</kinematic>
      </link>
      <joint name='yumi_joint_1_l' type='revolute'>
        <child>yumi_link_1_l</child>
        <parent>yumi_base_link</parent>
        <axis>
          <xyz>0.813834 0.341993 0.469803</xyz>
          <limit>
            <lower>-2.94088</lower>
            <upper>2.94088</upper>
            <effort>300</effort>
            <velocity>3.14159</velocity>
          </limit>
          <dynamics>
            <damping>0.5</damping>
            <friction>0</friction>
            <spring_reference>0</spring_reference>
            <spring_stiffness>0</spring_stiffness>
          </dynamics>
          <use_parent_model_frame>1</use_parent_model_frame>
        </axis>
      </joint>
      <link name='yumi_link_2_l'>
        <pose frame=''>0.117787 0.125209 0.57813 2.5489 -0.5716 2.318</pose>
        <inertial>
          <pose frame=''>0 0 0 0 -0 0</pose>
          <mass>2</mass>
          <inertia>
            <ixx>0.1</ixx>
            <ixy>0</ixy>
            <ixz>0</ixz>
            <iyy>0.1</iyy>
            <iyz>0</iyz>
            <izz>0.1</izz>
          </inertia>
        </inertial>
        <collision name='yumi_link_2_l_collision'>
          <pose frame=''>0 0 0 0 -0 0</pose>
          <geometry>
            <mesh>
              <scale>1 1 1</scale>
              <uri>/home/charles/yumi_depends_ws/src/yumi/yumi_description/meshes/coarse/link_2.stl</uri>
            </mesh>
          </geometry>
          <max_contacts>10</max_contacts>
          <surface>
            <contact>
              <ode/>
            </contact>
            <bounce/>
            <friction>
              <torsional>
                <ode/>
              </torsional>
              <ode/>
            </friction>
          </surface>
        </collision>
        <visual name='yumi_link_2_l_visual'>
          <pose frame=''>0 0 0 0 -0 0</pose>
          <geometry>
            <mesh>
              <scale>1 1 1</scale>
              <uri>/home/charles/yumi_depends_ws/src/yumi/yumi_description/meshes/link_2.stl</uri>
            </mesh>
          </geometry>
        </visual>
        <self_collide>0</self_collide>
        <enable_wind>0</enable_wind>
        <kinematic>0</kinematic>
      </link>
      <joint name='yumi_joint_2_l' type='revolute'>
        <child>yumi_link_2_l</child>
        <parent>yumi_link_1_l</parent>
        <axis>
          <xyz>0.104847 0.708787 -0.697587</xyz>
          <limit>
            <lower>-2.50455</lower>
            <upper>0.759218</upper>
            <effort>300</effort>
            <velocity>3.14159</velocity>
          </limit>
          <dynamics>
            <damping>0.5</damping>
            <friction>0</friction>
            <spring_reference>0</spring_reference>
            <spring_stiffness>0</spring_stiffness>
          </dynamics>
          <use_parent_model_frame>1</use_parent_model_frame>
        </axis>
      </joint>
      <link name='yumi_link_3_l'>
        <pose frame=''>0.275588 0.165806 0.643096 0.9781 -0.5716 2.318</pose>
        <inertial>
          <pose frame=''>0 0 0 0 -0 0</pose>
          <mass>2</mass>
          <inertia>
            <ixx>0.1</ixx>
            <ixy>0</ixy>
            <ixz>0</ixz>
            <iyy>0.1</iyy>
            <iyz>0</iyz>
            <izz>0.1</izz>
          </inertia>
        </inertial>
        <collision name='yumi_link_3_l_collision'>
          <pose frame=''>0 0 0 0 -0 0</pose>
          <geometry>
            <mesh>
              <scale>1 1 1</scale>
              <uri>/home/charles/yumi_depends_ws/src/yumi/yumi_description/meshes/coarse/link_3.stl</uri>
            </mesh>
          </geometry>
          <max_contacts>10</max_contacts>
          <surface>
            <contact>
              <ode/>
            </contact>
            <bounce/>
            <friction>
              <torsional>
                <ode/>
              </torsional>
              <ode/>
            </friction>
          </surface>
        </collision>
        <visual name='yumi_link_3_l_visual'>
          <pose frame=''>0 0 0 0 -0 0</pose>
          <geometry>
            <mesh>
              <scale>1 1 1</scale>
              <uri>/home/charles/yumi_depends_ws/src/yumi/yumi_description/meshes/link_3.stl</uri>
            </mesh>
          </geometry>
        </visual>
        <self_collide>0</self_collide>
        <enable_wind>0</enable_wind>
        <kinematic>0</kinematic>
      </link>
      <joint name='yumi_joint_7_l' type='revolute'>
        <child>yumi_link_3_l</child>
        <parent>yumi_link_2_l</parent>
        <axis>
          <xyz>0.813834 0.341993 0.469803</xyz>
          <limit>
            <lower>-2.94088</lower>
            <upper>2.94088</upper>
            <effort>300</effort>
            <velocity>3.14159</velocity>
          </limit>
          <dynamics>
            <damping>0.5</damping>
            <friction>0</friction>
            <spring_reference>0</spring_reference>
            <spring_stiffness>0</spring_stiffness>
          </dynamics>
          <use_parent_model_frame>1</use_parent_model_frame>
        </axis>
      </joint>
      <link name='yumi_link_4_l'>
        <pose frame=''>0.363599 0.166892 0.657428 -2.48197 -0.489067 0.397819</pose>
        <inertial>
          <pose frame=''>0 0 0 0 -0 0</pose>
          <mass>2</mass>
          <inertia>
            <ixx>0.1</ixx>
            <ixy>0</ixy>
            <ixz>0</ixz>
            <iyy>0.1</iyy>
            <iyz>0</iyz>
            <izz>0.1</izz>
          </inertia>
        </inertial>
        <collision name='yumi_link_4_l_collision'>
          <pose frame=''>0 0 0 0 -0 0</pose>
          <geometry>
            <mesh>
              <scale>1 1 1</scale>
              <uri>/home/charles/yumi_depends_ws/src/yumi/yumi_description/meshes/coarse/link_4.stl</uri>
            </mesh>
          </geometry>
          <max_contacts>10</max_contacts>
          <surface>
            <contact>
              <ode/>
            </contact>
            <bounce/>
            <friction>
              <torsional>
                <ode/>
              </torsional>
              <ode/>
            </friction>
          </surface>
        </collision>
        <visual name='yumi_link_4_l_visual'>
          <pose frame=''>0 0 0 0 -0 0</pose>
          <geometry>
            <mesh>
              <scale>1 1 1</scale>
              <uri>/home/charles/yumi_depends_ws/src/yumi/yumi_description/meshes/link_4.stl</uri>
            </mesh>
          </geometry>
        </visual>
        <self_collide>0</self_collide>
        <enable_wind>0</enable_wind>
        <kinematic>0</kinematic>
      </link>
      <joint name='yumi_joint_3_l' type='revolute'>
        <child>yumi_link_4_l</child>
        <parent>yumi_link_3_l</parent>
        <axis>
          <xyz>0.104847 0.708787 -0.697587</xyz>
          <limit>
            <lower>-2.15548</lower>
            <upper>1.39626</upper>
            <effort>300</effort>
            <velocity>3.14159</velocity>
          </limit>
          <dynamics>
            <damping>0.5</damping>
            <friction>0</friction>
            <spring_reference>0</spring_reference>
            <spring_stiffness>0</spring_stiffness>
          </dynamics>
          <use_parent_model_frame>1</use_parent_model_frame>
        </axis>
      </joint>
      <link name='yumi_link_5_l'>
        <pose frame=''>0.490643 0.079182 0.587404 2.23042 -0.489067 0.397819</pose>
        <inertial>
          <pose frame=''>0 0 0 0 -0 0</pose>
          <mass>2</mass>
          <inertia>
            <ixx>0.1</ixx>
            <ixy>0</ixy>
            <ixz>0</ixz>
            <iyy>0.1</iyy>
            <iyz>0</iyz>
            <izz>0.1</izz>
          </inertia>
        </inertial>
        <collision name='yumi_link_5_l_collision'>
          <pose frame=''>0 0 0 0 -0 0</pose>
          <geometry>
            <mesh>
              <scale>1 1 1</scale>
              <uri>/home/charles/yumi_depends_ws/src/yumi/yumi_description/meshes/coarse/link_5.stl</uri>
            </mesh>
          </geometry>
          <max_contacts>10</max_contacts>
          <surface>
            <contact>
              <ode/>
            </contact>
            <bounce/>
            <friction>
              <torsional>
                <ode/>
              </torsional>
              <ode/>
            </friction>
          </surface>
        </collision>
        <visual name='yumi_link_5_l_visual'>
          <pose frame=''>0 0 0 0 -0 0</pose>
          <geometry>
            <mesh>
              <scale>1 1 1</scale>
              <uri>/home/charles/yumi_depends_ws/src/yumi/yumi_description/meshes/link_5.stl</uri>
            </mesh>
          </geometry>
        </visual>
        <self_collide>0</self_collide>
        <enable_wind>0</enable_wind>
        <kinematic>0</kinematic>
      </link>
      <joint name='yumi_joint_4_l' type='revolute'>
        <child>yumi_link_5_l</child>
        <parent>yumi_link_4_l</parent>
        <axis>
          <xyz>0.57156 -0.616978 -0.540978</xyz>
          <limit>
            <lower>-5.06145</lower>
            <upper>5.06145</upper>
            <effort>300</effort>
            <velocity>6.98132</velocity>
          </limit>
          <dynamics>
            <damping>0.5</damping>
            <friction>0</friction>
            <spring_reference>0</spring_reference>
            <spring_stiffness>0</spring_stiffness>
          </dynamics>
          <use_parent_model_frame>1</use_parent_model_frame>
        </axis>
      </joint>
      <link name='yumi_link_6_l'>
        <pose frame=''>0.526049 0.00801 0.520411 -2.48197 -0.489067 0.397819</pose>
        <inertial>
          <pose frame=''>0 0 0 0 -0 0</pose>
          <mass>2</mass>
          <inertia>
            <ixx>0.1</ixx>
            <ixy>0</ixy>
            <ixz>0</ixz>
            <iyy>0.1</iyy>
            <iyz>0</iyz>
            <izz>0.1</izz>
          </inertia>
        </inertial>
        <collision name='yumi_link_6_l_collision'>
          <pose frame=''>0 0 0 0 -0 0</pose>
          <geometry>
            <mesh>
              <scale>1 1 1</scale>
              <uri>/home/charles/yumi_depends_ws/src/yumi/yumi_description/meshes/coarse/link_6.stl</uri>
            </mesh>
          </geometry>
          <max_contacts>10</max_contacts>
          <surface>
            <contact>
              <ode/>
            </contact>
            <bounce/>
            <friction>
              <torsional>
                <ode/>
              </torsional>
              <ode/>
            </friction>
          </surface>
        </collision>
        <visual name='yumi_link_6_l_visual'>
          <pose frame=''>0 0 0 0 -0 0</pose>
          <geometry>
            <mesh>
              <scale>1 1 1</scale>
              <uri>/home/charles/yumi_depends_ws/src/yumi/yumi_description/meshes/link_6.stl</uri>
            </mesh>
          </geometry>
        </visual>
        <self_collide>0</self_collide>
        <enable_wind>0</enable_wind>
        <kinematic>0</kinematic>
      </link>
      <joint name='yumi_joint_5_l' type='revolute'>
        <child>yumi_link_6_l</child>
        <parent>yumi_link_5_l</parent>
        <axis>
          <xyz>0.104847 0.708787 -0.697587</xyz>
          <limit>
            <lower>-1.53589</lower>
            <upper>2.40855</upper>
            <effort>300</effort>
            <velocity>6.98132</velocity>
          </limit>
          <dynamics>
            <damping>0.5</damping>
            <friction>0</friction>
            <spring_reference>0</spring_reference>
            <spring_stiffness>0</spring_stiffness>
          </dynamics>
          <use_parent_model_frame>1</use_parent_model_frame>
        </axis>
      </joint>
      <link name='yumi_link_7_l'>
        <pose frame=''>0.564597 -0.000649 0.517407 2.23042 -0.489067 0.397819</pose>
        <inertial>
          <pose frame=''>0 0 0.000636 0 -0 0</pose>
          <mass>2.2</mass>
          <inertia>
            <ixx>0.100109</ixx>
            <ixy>0</ixy>
            <ixz>0</ixz>
            <iyy>0.100109</iyy>
            <iyz>0</iyz>
            <izz>0.1001</izz>
          </inertia>
        </inertial>
        <collision name='yumi_link_7_l_collision'>
          <pose frame=''>0 0 0 0 -0 0</pose>
          <geometry>
            <mesh>
              <scale>1 1 1</scale>
              <uri>/home/charles/yumi_depends_ws/src/yumi/yumi_description/meshes/coarse/link_7.stl</uri>
            </mesh>
          </geometry>
          <max_contacts>10</max_contacts>
          <surface>
            <contact>
              <ode/>
            </contact>
            <bounce/>
            <friction>
              <torsional>
                <ode/>
              </torsional>
              <ode/>
            </friction>
          </surface>
        </collision>
        <collision name='yumi_link_7_l_fixed_joint_lump__gripper_l_base_collision_1'>
          <pose frame=''>0 0 0.007 0 -0 -3.14159</pose>
          <geometry>
            <mesh>
              <scale>1 1 1</scale>
              <uri>/home/charles/yumi_depends_ws/src/yumi/yumi_description/meshes/gripper/coarse/base.stl</uri>
            </mesh>
          </geometry>
          <surface>
            <contact>
              <ode/>
            </contact>
            <friction>
              <ode>
                <mu>0.2</mu>
                <mu2>0.2</mu2>
              </ode>
              <torsional>
                <ode/>
              </torsional>
            </friction>
            <bounce/>
          </surface>
          <max_contacts>10</max_contacts>
        </collision>
        <visual name='yumi_link_7_l_visual'>
          <pose frame=''>0 0 0 0 -0 0</pose>
          <geometry>
            <mesh>
              <scale>1 1 1</scale>
              <uri>/home/charles/yumi_depends_ws/src/yumi/yumi_description/meshes/link_7.stl</uri>
            </mesh>
          </geometry>
        </visual>
        <visual name='yumi_link_7_l_fixed_joint_lump__gripper_l_base_visual_1'>
          <pose frame=''>0 0 0.007 0 -0 -3.14159</pose>
          <geometry>
            <mesh>
              <scale>1 1 1</scale>
              <uri>/home/charles/yumi_depends_ws/src/yumi/yumi_description/meshes/gripper/base.stl</uri>
            </mesh>
          </geometry>
          <material>
            <script>
              <name>Gazebo/Light_Grey</name>
              <uri>file://media/materials/scripts/gazebo.material</uri>
            </script>
          </material>
        </visual>
        <gravity>1</gravity>
        <velocity_decay/>
        <self_collide>0</self_collide>
        <enable_wind>0</enable_wind>
        <kinematic>0</kinematic>
      </link>
      <joint name='yumi_joint_6_l' type='revolute'>
        <child>yumi_link_7_l</child>
        <parent>yumi_link_6_l</parent>
        <axis>
          <xyz>0.57156 -0.616978 -0.540978</xyz>
          <limit>
            <lower>-3.9968</lower>
            <upper>3.9968</upper>
            <effort>300</effort>
            <velocity>6.98132</velocity>
          </limit>
          <dynamics>
            <damping>0.5</damping>
            <friction>0</friction>
            <spring_reference>0</spring_reference>
            <spring_stiffness>0</spring_stiffness>
          </dynamics>
          <use_parent_model_frame>1</use_parent_model_frame>
        </axis>
      </joint>
      <link name='gripper_l_finger_r'>
        <pose frame=''>0.615756 -0.061216 0.472875 -2.23042 0.489067 -2.74377</pose>
        <inertial>
          <pose frame=''>0 0 0 0 -0 0</pose>
          <mass>0.04</mass>
          <inertia>
            <ixx>1.66667e-05</ixx>
            <ixy>0</ixy>
            <ixz>0</ixz>
            <iyy>1.66667e-05</iyy>
            <iyz>0</iyz>
            <izz>1.66667e-05</izz>
          </inertia>
        </inertial>
        <collision name='gripper_l_finger_r_collision'>
          <pose frame=''>0 0 0 0 -0 0</pose>
          <geometry>
            <mesh>
              <scale>1 1 1</scale>
              <uri>/home/charles/yumi_depends_ws/src/yumi/yumi_description/meshes/gripper/coarse/finger.stl</uri>
            </mesh>
          </geometry>
          <max_contacts>10</max_contacts>
          <surface>
            <contact>
              <ode/>
            </contact>
            <bounce/>
            <friction>
              <torsional>
                <ode/>
              </torsional>
              <ode/>
            </friction>
          </surface>
        </collision>
        <visual name='gripper_l_finger_r_visual'>
          <pose frame=''>0 0 0 0 -0 0</pose>
          <geometry>
            <mesh>
              <scale>1 1 1</scale>
              <uri>/home/charles/yumi_depends_ws/src/yumi/yumi_description/meshes/gripper/finger.stl</uri>
            </mesh>
          </geometry>
        </visual>
        <self_collide>0</self_collide>
        <enable_wind>0</enable_wind>
        <kinematic>0</kinematic>
      </link>
      <joint name='gripper_l_joint' type='prismatic'>
        <child>gripper_l_finger_r</child>
        <parent>yumi_link_7_l</parent>
        <axis>
          <xyz>0.813834 0.341993 0.469803</xyz>
          <limit>
            <lower>0</lower>
            <upper>0.025</upper>
            <effort>20</effort>
            <velocity>2</velocity>
          </limit>
          <dynamics>
            <damping>1</damping>
            <friction>0</friction>
            <spring_reference>0</spring_reference>
            <spring_stiffness>0</spring_stiffness>
          </dynamics>
          <use_parent_model_frame>1</use_parent_model_frame>
        </axis>
      </joint>
      <link name='gripper_l_finger_l'>
        <pose frame=''>0.617119 -0.052001 0.463806 2.23042 -0.489067 0.397819</pose>
        <inertial>
          <pose frame=''>0 0 0 0 -0 0</pose>
          <mass>0.04</mass>
          <inertia>
            <ixx>1.66667e-05</ixx>
            <ixy>0</ixy>
            <ixz>0</ixz>
            <iyy>1.66667e-05</iyy>
            <iyz>0</iyz>
            <izz>1.66667e-05</izz>
          </inertia>
        </inertial>
        <collision name='gripper_l_finger_l_collision'>
          <pose frame=''>0 0 0 0 -0 0</pose>
          <geometry>
            <mesh>
              <scale>1 1 1</scale>
              <uri>/home/charles/yumi_depends_ws/src/yumi/yumi_description/meshes/gripper/coarse/finger.stl</uri>
            </mesh>
          </geometry>
          <max_contacts>10</max_contacts>
          <surface>
            <contact>
              <ode/>
            </contact>
            <bounce/>
            <friction>
              <torsional>
                <ode/>
              </torsional>
              <ode/>
            </friction>
          </surface>
        </collision>
        <visual name='gripper_l_finger_l_visual'>
          <pose frame=''>0 0 0 0 -0 0</pose>
          <geometry>
            <mesh>
              <scale>1 1 1</scale>
              <uri>/home/charles/yumi_depends_ws/src/yumi/yumi_description/meshes/gripper/finger.stl</uri>
            </mesh>
          </geometry>
        </visual>
        <self_collide>0</self_collide>
        <enable_wind>0</enable_wind>
        <kinematic>0</kinematic>
      </link>
      <joint name='gripper_l_joint_m' type='prismatic'>
        <child>gripper_l_finger_l</child>
        <parent>yumi_link_7_l</parent>
        <axis>
          <xyz>-0.813834 -0.341993 -0.469803</xyz>
          <limit>
            <lower>0</lower>
            <upper>0.025</upper>
            <effort>20</effort>
            <velocity>2</velocity>
          </limit>
          <dynamics>
            <damping>1</damping>
            <friction>0</friction>
            <spring_reference>0</spring_reference>
            <spring_stiffness>0</spring_stiffness>
          </dynamics>
          <use_parent_model_frame>1</use_parent_model_frame>
        </axis>
      </joint>
      <link name='yumi_link_1_r'>
        <pose frame=''>0.05355 -0.0725 0.51492 -0.9795 -0.5682 -2.3155</pose>
        <inertial>
          <pose frame=''>0 -0.03 0.12 0 -0 0</pose>
          <mass>2</mass>
          <inertia>
            <ixx>0.1</ixx>
            <ixy>0</ixy>
            <ixz>0</ixz>
            <iyy>0.1</iyy>
            <iyz>0</iyz>
            <izz>0.1</izz>
          </inertia>
        </inertial>
        <collision name='yumi_link_1_r_collision'>
          <pose frame=''>0 0 0 0 -0 0</pose>
          <geometry>
            <mesh>
              <scale>1 1 1</scale>
              <uri>/home/charles/yumi_depends_ws/src/yumi/yumi_description/meshes/coarse/link_1.stl</uri>
            </mesh>
          </geometry>
          <max_contacts>10</max_contacts>
          <surface>
            <contact>
              <ode/>
            </contact>
            <bounce/>
            <friction>
              <torsional>
                <ode/>
              </torsional>
              <ode/>
            </friction>
          </surface>
        </collision>
        <visual name='yumi_link_1_r_visual'>
          <pose frame=''>0 0 0 0 -0 0</pose>
          <geometry>
            <mesh>
              <scale>1 1 1</scale>
              <uri>/home/charles/yumi_depends_ws/src/yumi/yumi_description/meshes/link_1.stl</uri>
            </mesh>
          </geometry>
        </visual>
        <self_collide>0</self_collide>
        <enable_wind>0</enable_wind>
        <kinematic>0</kinematic>
      </link>
      <joint name='yumi_joint_1_r' type='revolute'>
        <child>yumi_link_1_r</child>
        <parent>yumi_base_link</parent>
        <axis>
          <xyz>0.813754 -0.342122 0.469848</xyz>
          <limit>
            <lower>-2.94088</lower>
            <upper>2.94088</upper>
            <effort>300</effort>
            <velocity>3.14159</velocity>
          </limit>
          <dynamics>
            <damping>0.5</damping>
            <friction>0</friction>
            <spring_reference>0</spring_reference>
            <spring_stiffness>0</spring_stiffness>
          </dynamics>
          <use_parent_model_frame>1</use_parent_model_frame>
        </axis>
      </joint>
      <link name='yumi_link_2_r'>
        <pose frame=''>0.117788 -0.125305 0.578048 0.591296 -0.5682 -2.3155</pose>
        <inertial>
          <pose frame=''>0 0 0 0 -0 0</pose>
          <mass>2</mass>
          <inertia>
            <ixx>0.1</ixx>
            <ixy>0</ixy>
            <ixz>0</ixz>
            <iyy>0.1</iyy>
            <iyz>0</iyz>
            <izz>0.1</izz>
          </inertia>
        </inertial>
        <collision name='yumi_link_2_r_collision'>
          <pose frame=''>0 0 0 0 -0 0</pose>
          <geometry>
            <mesh>
              <scale>1 1 1</scale>
              <uri>/home/charles/yumi_depends_ws/src/yumi/yumi_description/meshes/coarse/link_2.stl</uri>
            </mesh>
          </geometry>
          <max_contacts>10</max_contacts>
          <surface>
            <contact>
              <ode/>
            </contact>
            <bounce/>
            <friction>
              <torsional>
                <ode/>
              </torsional>
              <ode/>
            </friction>
          </surface>
        </collision>
        <visual name='yumi_link_2_r_visual'>
          <pose frame=''>0 0 0 0 -0 0</pose>
          <geometry>
            <mesh>
              <scale>1 1 1</scale>
              <uri>/home/charles/yumi_depends_ws/src/yumi/yumi_description/meshes/link_2.stl</uri>
            </mesh>
          </geometry>
        </visual>
        <self_collide>0</self_collide>
        <enable_wind>0</enable_wind>
        <kinematic>0</kinematic>
      </link>
      <joint name='yumi_joint_2_r' type='revolute'>
        <child>yumi_link_2_r</child>
        <parent>yumi_link_1_r</parent>
        <axis>
          <xyz>-0.107089 0.706299 0.699767</xyz>
          <limit>
            <lower>-2.50455</lower>
            <upper>0.759218</upper>
            <effort>300</effort>
            <velocity>3.14159</velocity>
          </limit>
          <dynamics>
            <damping>0.5</damping>
            <friction>0</friction>
            <spring_reference>0</spring_reference>
            <spring_stiffness>0</spring_stiffness>
          </dynamics>
          <use_parent_model_frame>1</use_parent_model_frame>
        </axis>
      </joint>
      <link name='yumi_link_3_r'>
        <pose frame=''>0.275566 -0.165841 0.643109 -0.9795 -0.5682 -2.3155</pose>
        <inertial>
          <pose frame=''>0 0 0 0 -0 0</pose>
          <mass>2</mass>
          <inertia>
            <ixx>0.1</ixx>
            <ixy>0</ixy>
            <ixz>0</ixz>
            <iyy>0.1</iyy>
            <iyz>0</iyz>
            <izz>0.1</izz>
          </inertia>
        </inertial>
        <collision name='yumi_link_3_r_collision'>
          <pose frame=''>0 0 0 0 -0 0</pose>
          <geometry>
            <mesh>
              <scale>1 1 1</scale>
              <uri>/home/charles/yumi_depends_ws/src/yumi/yumi_description/meshes/coarse/link_3.stl</uri>
            </mesh>
          </geometry>
          <max_contacts>10</max_contacts>
          <surface>
            <contact>
              <ode/>
            </contact>
            <bounce/>
            <friction>
              <torsional>
                <ode/>
              </torsional>
              <ode/>
            </friction>
          </surface>
        </collision>
        <visual name='yumi_link_3_r_visual'>
          <pose frame=''>0 0 0 0 -0 0</pose>
          <geometry>
            <mesh>
              <scale>1 1 1</scale>
              <uri>/home/charles/yumi_depends_ws/src/yumi/yumi_description/meshes/link_3.stl</uri>
            </mesh>
          </geometry>
        </visual>
        <self_collide>0</self_collide>
        <enable_wind>0</enable_wind>
        <kinematic>0</kinematic>
      </link>
      <joint name='yumi_joint_7_r' type='revolute'>
        <child>yumi_link_3_r</child>
        <parent>yumi_link_2_r</parent>
        <axis>
          <xyz>0.813754 -0.342122 0.469848</xyz>
          <limit>
            <lower>-2.94088</lower>
            <upper>2.94088</upper>
            <effort>300</effort>
            <velocity>3.14159</velocity>
          </limit>
          <dynamics>
            <damping>0.5</damping>
            <friction>0</friction>
            <spring_reference>0</spring_reference>
            <spring_stiffness>0</spring_stiffness>
          </dynamics>
          <use_parent_model_frame>1</use_parent_model_frame>
        </axis>
      </joint>
      <link name='yumi_link_4_r'>
        <pose frame=''>0.363558 -0.166821 0.657563 -0.655546 -0.489119 -0.397989</pose>
        <inertial>
          <pose frame=''>0 0 0 0 -0 0</pose>
          <mass>2</mass>
          <inertia>
            <ixx>0.1</ixx>
            <ixy>0</ixy>
            <ixz>0</ixz>
            <iyy>0.1</iyy>
            <iyz>0</iyz>
            <izz>0.1</izz>
          </inertia>
        </inertial>
        <collision name='yumi_link_4_r_collision'>
          <pose frame=''>0 0 0 0 -0 0</pose>
          <geometry>
            <mesh>
              <scale>1 1 1</scale>
              <uri>/home/charles/yumi_depends_ws/src/yumi/yumi_description/meshes/coarse/link_4.stl</uri>
            </mesh>
          </geometry>
          <max_contacts>10</max_contacts>
          <surface>
            <contact>
              <ode/>
            </contact>
            <bounce/>
            <friction>
              <torsional>
                <ode/>
              </torsional>
              <ode/>
            </friction>
          </surface>
        </collision>
        <visual name='yumi_link_4_r_visual'>
          <pose frame=''>0 0 0 0 -0 0</pose>
          <geometry>
            <mesh>
              <scale>1 1 1</scale>
              <uri>/home/charles/yumi_depends_ws/src/yumi/yumi_description/meshes/link_4.stl</uri>
            </mesh>
          </geometry>
        </visual>
        <self_collide>0</self_collide>
        <enable_wind>0</enable_wind>
        <kinematic>0</kinematic>
      </link>
      <joint name='yumi_joint_3_r' type='revolute'>
        <child>yumi_link_4_r</child>
        <parent>yumi_link_3_r</parent>
        <axis>
          <xyz>-0.107089 0.706299 0.699767</xyz>
          <limit>
            <lower>-2.15548</lower>
            <upper>1.39626</upper>
            <effort>300</effort>
            <velocity>3.14159</velocity>
          </limit>
          <dynamics>
            <damping>0.5</damping>
            <friction>0</friction>
            <spring_reference>0</spring_reference>
            <spring_stiffness>0</spring_stiffness>
          </dynamics>
          <use_parent_model_frame>1</use_parent_model_frame>
        </axis>
      </joint>
      <link name='yumi_link_5_r'>
        <pose frame=''>0.49055 -0.07866 0.588013 -2.22634 -0.489119 -0.397989</pose>
        <inertial>
          <pose frame=''>0 0 0 0 -0 0</pose>
          <mass>2</mass>
          <inertia>
            <ixx>0.1</ixx>
            <ixy>0</ixy>
            <ixz>0</ixz>
            <iyy>0.1</iyy>
            <iyz>0</iyz>
            <izz>0.1</izz>
          </inertia>
        </inertial>
        <collision name='yumi_link_5_r_collision'>
          <pose frame=''>0 0 0 0 -0 0</pose>
          <geometry>
            <mesh>
              <scale>1 1 1</scale>
              <uri>/home/charles/yumi_depends_ws/src/yumi/yumi_description/meshes/coarse/link_5.stl</uri>
            </mesh>
          </geometry>
          <max_contacts>10</max_contacts>
          <surface>
            <contact>
              <ode/>
            </contact>
            <bounce/>
            <friction>
              <torsional>
                <ode/>
              </torsional>
              <ode/>
            </friction>
          </surface>
        </collision>
        <visual name='yumi_link_5_r_visual'>
          <pose frame=''>0 0 0 0 -0 0</pose>
          <geometry>
            <mesh>
              <scale>1 1 1</scale>
              <uri>/home/charles/yumi_depends_ws/src/yumi/yumi_description/meshes/link_5.stl</uri>
            </mesh>
          </geometry>
        </visual>
        <self_collide>0</self_collide>
        <enable_wind>0</enable_wind>
        <kinematic>0</kinematic>
      </link>
      <joint name='yumi_joint_4_r' type='revolute'>
        <child>yumi_link_5_r</child>
        <parent>yumi_link_4_r</parent>
        <axis>
          <xyz>0.571259 0.619754 -0.538116</xyz>
          <limit>
            <lower>-5.06145</lower>
            <upper>5.06145</upper>
            <effort>300</effort>
            <velocity>6.98132</velocity>
          </limit>
          <dynamics>
            <damping>0.5</damping>
            <friction>0</friction>
            <spring_reference>0</spring_reference>
            <spring_stiffness>0</spring_stiffness>
          </dynamics>
          <use_parent_model_frame>1</use_parent_model_frame>
        </axis>
      </joint>
      <link name='yumi_link_6_r'>
        <pose frame=''>0.525927 -0.007205 0.521306 -0.655546 -0.489119 -0.397989</pose>
        <inertial>
          <pose frame=''>0 0 0 0 -0 0</pose>
          <mass>2</mass>
          <inertia>
            <ixx>0.1</ixx>
            <ixy>0</ixy>
            <ixz>0</ixz>
            <iyy>0.1</iyy>
            <iyz>0</iyz>
            <izz>0.1</izz>
          </inertia>
        </inertial>
        <collision name='yumi_link_6_r_collision'>
          <pose frame=''>0 0 0 0 -0 0</pose>
          <geometry>
            <mesh>
              <scale>1 1 1</scale>
              <uri>/home/charles/yumi_depends_ws/src/yumi/yumi_description/meshes/coarse/link_6.stl</uri>
            </mesh>
          </geometry>
          <max_contacts>10</max_contacts>
          <surface>
            <contact>
              <ode/>
            </contact>
            <bounce/>
            <friction>
              <torsional>
                <ode/>
              </torsional>
              <ode/>
            </friction>
          </surface>
        </collision>
        <visual name='yumi_link_6_r_visual'>
          <pose frame=''>0 0 0 0 -0 0</pose>
          <geometry>
            <mesh>
              <scale>1 1 1</scale>
              <uri>/home/charles/yumi_depends_ws/src/yumi/yumi_description/meshes/link_6.stl</uri>
            </mesh>
          </geometry>
        </visual>
        <self_collide>0</self_collide>
        <enable_wind>0</enable_wind>
        <kinematic>0</kinematic>
      </link>
      <joint name='yumi_joint_5_r' type='revolute'>
        <child>yumi_link_6_r</child>
        <parent>yumi_link_5_r</parent>
        <axis>
          <xyz>-0.107089 0.706299 0.699767</xyz>
          <limit>
            <lower>-1.53589</lower>
            <upper>2.40855</upper>
            <effort>300</effort>
            <velocity>6.98132</velocity>
          </limit>
          <dynamics>
            <damping>0.5</damping>
            <friction>0</friction>
            <spring_reference>0</spring_reference>
            <spring_stiffness>0</spring_stiffness>
          </dynamics>
          <use_parent_model_frame>1</use_parent_model_frame>
        </axis>
      </joint>
      <link name='yumi_link_7_r'>
        <pose frame=''>0.564465 0.00153 0.518386 -2.22634 -0.489119 -0.397989</pose>
        <inertial>
          <pose frame=''>0 0 0.000636 0 -0 0</pose>
          <mass>2.2</mass>
          <inertia>
            <ixx>0.100109</ixx>
            <ixy>0</ixy>
            <ixz>0</ixz>
            <iyy>0.100109</iyy>
            <iyz>0</iyz>
            <izz>0.1001</izz>
          </inertia>
        </inertial>
        <collision name='yumi_link_7_r_collision'>
          <pose frame=''>0 0 0 0 -0 0</pose>
          <geometry>
            <mesh>
              <scale>1 1 1</scale>
              <uri>/home/charles/yumi_depends_ws/src/yumi/yumi_description/meshes/coarse/link_7.stl</uri>
            </mesh>
          </geometry>
          <max_contacts>10</max_contacts>
          <surface>
            <contact>
              <ode/>
            </contact>
            <bounce/>
            <friction>
              <torsional>
                <ode/>
              </torsional>
              <ode/>
            </friction>
          </surface>
        </collision>
        <collision name='yumi_link_7_r_fixed_joint_lump__gripper_r_base_collision_1'>
          <pose frame=''>0 0 0.007 0 -0 -3.14159</pose>
          <geometry>
            <mesh>
              <scale>1 1 1</scale>
              <uri>/home/charles/yumi_depends_ws/src/yumi/yumi_description/meshes/gripper/coarse/base.stl</uri>
            </mesh>
          </geometry>
          <surface>
            <contact>
              <ode/>
            </contact>
            <friction>
              <ode>
                <mu>0.2</mu>
                <mu2>0.2</mu2>
              </ode>
              <torsional>
                <ode/>
              </torsional>
            </friction>
            <bounce/>
          </surface>
          <max_contacts>10</max_contacts>
        </collision>
        <visual name='yumi_link_7_r_visual'>
          <pose frame=''>0 0 0 0 -0 0</pose>
          <geometry>
            <mesh>
              <scale>1 1 1</scale>
              <uri>/home/charles/yumi_depends_ws/src/yumi/yumi_description/meshes/link_7.stl</uri>
            </mesh>
          </geometry>
        </visual>
        <visual name='yumi_link_7_r_fixed_joint_lump__gripper_r_base_visual_1'>
          <pose frame=''>0 0 0.007 0 -0 -3.14159</pose>
          <geometry>
            <mesh>
              <scale>1 1 1</scale>
              <uri>/home/charles/yumi_depends_ws/src/yumi/yumi_description/meshes/gripper/base.stl</uri>
            </mesh>
          </geometry>
          <material>
            <script>
              <name>Gazebo/Light_Grey</name>
              <uri>file://media/materials/scripts/gazebo.material</uri>
            </script>
          </material>
        </visual>
        <gravity>1</gravity>
        <velocity_decay/>
        <self_collide>0</self_collide>
        <enable_wind>0</enable_wind>
        <kinematic>0</kinematic>
      </link>
      <joint name='yumi_joint_6_r' type='revolute'>
        <child>yumi_link_7_r</child>
        <parent>yumi_link_6_r</parent>
        <axis>
          <xyz>0.571259 0.619754 -0.538116</xyz>
          <limit>
            <lower>-3.9968</lower>
            <upper>3.9968</upper>
            <effort>300</effort>
            <velocity>6.98132</velocity>
          </limit>
          <dynamics>
            <damping>0.5</damping>
            <friction>0</friction>
            <spring_reference>0</spring_reference>
            <spring_stiffness>0</spring_stiffness>
          </dynamics>
          <use_parent_model_frame>1</use_parent_model_frame>
        </axis>
      </joint>
      <link name='gripper_r_finger_r'>
        <pose frame=''>0.616974 0.053151 0.465031 2.22634 0.489119 2.7436</pose>
        <inertial>
          <pose frame=''>0 0 0 0 -0 0</pose>
          <mass>0.04</mass>
          <inertia>
            <ixx>1.66667e-05</ixx>
            <ixy>0</ixy>
            <ixz>0</ixz>
            <iyy>1.66667e-05</iyy>
            <iyz>0</iyz>
            <izz>1.66667e-05</izz>
          </inertia>
        </inertial>
        <collision name='gripper_r_finger_r_collision'>
          <pose frame=''>0 0 0 0 -0 0</pose>
          <geometry>
            <mesh>
              <scale>1 1 1</scale>
              <uri>/home/charles/yumi_depends_ws/src/yumi/yumi_description/meshes/gripper/coarse/finger.stl</uri>
            </mesh>
          </geometry>
          <max_contacts>10</max_contacts>
          <surface>
            <contact>
              <ode/>
            </contact>
            <bounce/>
            <friction>
              <torsional>
                <ode/>
              </torsional>
              <ode/>
            </friction>
          </surface>
        </collision>
        <visual name='gripper_r_finger_r_visual'>
          <pose frame=''>0 0 0 0 -0 0</pose>
          <geometry>
            <mesh>
              <scale>1 1 1</scale>
              <uri>/home/charles/yumi_depends_ws/src/yumi/yumi_description/meshes/gripper/finger.stl</uri>
            </mesh>
          </geometry>
        </visual>
        <self_collide>0</self_collide>
        <enable_wind>0</enable_wind>
        <kinematic>0</kinematic>
      </link>
      <joint name='gripper_r_joint' type='prismatic'>
        <child>gripper_r_finger_r</child>
        <parent>yumi_link_7_r</parent>
        <axis>
          <xyz>0.813754 -0.342122 0.469848</xyz>
          <limit>
            <lower>0</lower>
            <upper>0.025</upper>
            <effort>20</effort>
            <velocity>2</velocity>
          </limit>
          <dynamics>
            <damping>1</damping>
            <friction>0</friction>
            <spring_reference>0</spring_reference>
            <spring_stiffness>0</spring_stiffness>
          </dynamics>
          <use_parent_model_frame>1</use_parent_model_frame>
        </axis>
      </joint>
      <link name='gripper_r_finger_l'>
        <pose frame=''>0.615582 0.062333 0.474128 -2.22634 -0.489119 -0.397989</pose>
        <inertial>
          <pose frame=''>0 0 0 0 -0 0</pose>
          <mass>0.04</mass>
          <inertia>
            <ixx>1.66667e-05</ixx>
            <ixy>0</ixy>
            <ixz>0</ixz>
            <iyy>1.66667e-05</iyy>
            <iyz>0</iyz>
            <izz>1.66667e-05</izz>
          </inertia>
        </inertial>
        <collision name='gripper_r_finger_l_collision'>
          <pose frame=''>0 0 0 0 -0 0</pose>
          <geometry>
            <mesh>
              <scale>1 1 1</scale>
              <uri>/home/charles/yumi_depends_ws/src/yumi/yumi_description/meshes/gripper/coarse/finger.stl</uri>
            </mesh>
          </geometry>
          <max_contacts>10</max_contacts>
          <surface>
            <contact>
              <ode/>
            </contact>
            <bounce/>
            <friction>
              <torsional>
                <ode/>
              </torsional>
              <ode/>
            </friction>
          </surface>
        </collision>
        <visual name='gripper_r_finger_l_visual'>
          <pose frame=''>0 0 0 0 -0 0</pose>
          <geometry>
            <mesh>
              <scale>1 1 1</scale>
              <uri>/home/charles/yumi_depends_ws/src/yumi/yumi_description/meshes/gripper/finger.stl</uri>
            </mesh>
          </geometry>
        </visual>
        <self_collide>0</self_collide>
        <enable_wind>0</enable_wind>
        <kinematic>0</kinematic>
      </link>
      <joint name='gripper_r_joint_m' type='prismatic'>
        <child>gripper_r_finger_l</child>
        <parent>yumi_link_7_r</parent>
        <axis>
          <xyz>-0.813754 0.342122 -0.469848</xyz>
          <limit>
            <lower>0</lower>
            <upper>0.025</upper>
            <effort>20</effort>
            <velocity>2</velocity>
          </limit>
          <dynamics>
            <damping>1</damping>
            <friction>0</friction>
            <spring_reference>0</spring_reference>
            <spring_stiffness>0</spring_stiffness>
          </dynamics>
          <use_parent_model_frame>1</use_parent_model_frame>
        </axis>
      </joint>
      <plugin name='gazebo_ros_controller' filename='libgazebo_ros_control.so'>
        <robotNamespace>/yumi</robotNamespace>
      </plugin>
      <plugin name='ft_sensor' filename='libgazebo_ros_ft_sensor.so'>
        <updateRate>100.0</updateRate>
        <topicName>ft_sensor_topic</topicName>
        <jointName>yumi_joint_6_l"</jointName>
        <robotNamespace>/</robotNamespace>
      </plugin>
      <plugin name='gazebo_grasp_fix' filename='libgazebo_grasp_fix.so'>
        <arm>
          <arm_name>right</arm_name>
          <palm_link>gripper_r_base</palm_link>
          <gripper_link>gripper_r_finger_r</gripper_link>
          <gripper_link>gripper_r_finger_l</gripper_link>
          <gripper_link>...</gripper_link>
        </arm>
        <forces_angle_tolerance>100</forces_angle_tolerance>
        <update_rate>4</update_rate>
        <grip_count_threshold>4</grip_count_threshold>
        <max_grip_count>8</max_grip_count>
        <release_tolerance>0.005</release_tolerance>
        <disable_collisions_on_attach>1</disable_collisions_on_attach>
        <contact_topic>__default_topic__</contact_topic>
        <robotNamespace>/</robotNamespace>
      </plugin>
      <plugin name='mimic_plugin' filename='libgazebo_mimic_plugin.so'>
        <joint>gripper_r_joint</joint>
        <mimicJoint>gripper_r_joint_m</mimicJoint>
        <multiplier>1.0</multiplier>
        <robotNamespace>/</robotNamespace>
      </plugin>
      <plugin name='gazebo_grasp_fix' filename='libgazebo_grasp_fix.so'>
        <arm>
          <arm_name>left</arm_name>
          <palm_link>gripper_l_base</palm_link>
          <gripper_link>gripper_l_finger_r</gripper_link>
          <gripper_link>gripper_l_finger_l</gripper_link>
          <gripper_link>...</gripper_link>
        </arm>
        <forces_angle_tolerance>100</forces_angle_tolerance>
        <update_rate>4</update_rate>
        <grip_count_threshold>4</grip_count_threshold>
        <max_grip_count>8</max_grip_count>
        <release_tolerance>0.005</release_tolerance>
        <disable_collisions_on_attach>1</disable_collisions_on_attach>
        <contact_topic>__default_topic__</contact_topic>
        <robotNamespace>/</robotNamespace>
      </plugin>
      <static>0</static>
      <plugin name='mimic_plugin' filename='libgazebo_mimic_plugin.so'>
        <joint>gripper_l_joint</joint>
        <mimicJoint>gripper_l_joint_m</mimicJoint>
        <multiplier>1.0</multiplier>
        <robotNamespace>/</robotNamespace>
      </plugin>
      <pose frame=''>0 0 0 0 -0 0</pose>
    </model>
    <model name='rektangl'>
      <link name='link_1'>
        <inertial>
          <mass>4.92614e-05</mass>
          <inertia>
            <ixx>5.32902e-08</ixx>
            <ixy>0</ixy>
            <ixz>0</ixz>
            <iyy>5.46743e-08</iyy>
            <iyz>0</iyz>
            <izz>3.85015e-09</izz>
          </inertia>
          <pose frame=''>0 0 0 0 -0 0</pose>
        </inertial>
        <pose frame=''>0 -0 0 0 -0 0</pose>
        <visual name='visual'>
          <pose frame=''>0 0 0 0 -0 0</pose>
          <geometry>
            <box>
              <size>0.025249 0.017331 0.11261</size>
            </box>
          </geometry>
          <material>
            <lighting>1</lighting>
            <script>
              <uri>file://media/materials/scripts/gazebo.material</uri>
              <name>Gazebo/Grey</name>
            </script>
          </material>
          <transparency>0</transparency>
          <cast_shadows>1</cast_shadows>
        </visual>
        <collision name='collision'>
          <laser_retro>0</laser_retro>
          <max_contacts>10</max_contacts>
          <pose frame=''>0 0 0 0 -0 0</pose>
          <geometry>
            <box>
              <size>0.025249 0.017331 0.11261</size>
            </box>
          </geometry>
          <surface>
            <friction>
              <ode>
                <mu>1</mu>
                <mu2>1</mu2>
                <fdir1>0 0 0</fdir1>
                <slip1>0</slip1>
                <slip2>0</slip2>
              </ode>
              <torsional>
                <coefficient>1</coefficient>
                <patch_radius>0</patch_radius>
                <surface_radius>0</surface_radius>
                <use_patch_radius>1</use_patch_radius>
                <ode>
                  <slip>0</slip>
                </ode>
              </torsional>
            </friction>
            <bounce>
              <restitution_coefficient>0</restitution_coefficient>
              <threshold>1e+06</threshold>
            </bounce>
            <contact>
              <collide_without_contact>0</collide_without_contact>
              <collide_without_contact_bitmask>1</collide_without_contact_bitmask>
              <collide_bitmask>1</collide_bitmask>
              <ode>
                <soft_cfm>0</soft_cfm>
                <soft_erp>0.2</soft_erp>
                <kp>1e+13</kp>
                <kd>1</kd>
                <max_vel>0.01</max_vel>
                <min_depth>0</min_depth>
              </ode>
              <bullet>
                <split_impulse>1</split_impulse>
                <split_impulse_penetration_threshold>-0.01</split_impulse_penetration_threshold>
                <soft_cfm>0</soft_cfm>
                <soft_erp>0.2</soft_erp>
                <kp>1e+13</kp>
                <kd>1</kd>
              </bullet>
            </contact>
          </surface>
        </collision>
        <self_collide>0</self_collide>
        <enable_wind>0</enable_wind>
        <kinematic>0</kinematic>
      </link>
      <static>0</static>
      <allow_auto_disable>1</allow_auto_disable>
      <pose frame=''>1.61735 -1.66281 0 0 -0 0</pose>
    </model>
    <state world_name='default'>
      <sim_time>98 290000000</sim_time>
      <real_time>187 696106428</real_time>
      <wall_time>1587546378 534810347</wall_time>
      <iterations>98290</iterations>
      <model name='coke_min'>
        <pose frame=''>0.510063 0.298406 0.047603 0.054723 -0.057256 -0.111137</pose>
        <scale>1 1 1</scale>
        <link name='link'>
          <pose frame=''>0.510063 0.298406 0.047603 0.054723 -0.057256 -0.111137</pose>
          <velocity>0 0 0 0 -0 0</velocity>
          <acceleration>1.78494 -0.561318 21.5212 -0.427756 -0.38114 -2.78566</acceleration>
          <wrench>0.696128 -0.218914 8.39326 0 -0 0</wrench>
        </link>
      </model>
      <model name='ground_plane'>
        <pose frame=''>0 0 0 0 -0 0</pose>
        <scale>1 1 1</scale>
        <link name='link'>
          <pose frame=''>0 0 0 0 -0 0</pose>
          <velocity>0 0 0 0 -0 0</velocity>
          <acceleration>0 0 0 0 -0 0</acceleration>
          <wrench>0 0 0 0 -0 0</wrench>
        </link>
      </model>
      <model name='rektangl'>
        <pose frame=''>1.61735 -1.66281 0.056305 -2e-06 -1.4e-05 0.001949</pose>
        <scale>1 1 1</scale>
        <link name='link_1'>
          <pose frame=''>1.61735 -1.66281 0.056305 -2e-06 -1.4e-05 0.001949</pose>
          <velocity>0 0 0 0 -0 0</velocity>
          <acceleration>1.77098 -0.33652 0.845143 0.93313 -0.135435 1.43636</acceleration>
          <wrench>8.7e-05 -1.7e-05 4.2e-05 0 -0 0</wrench>
        </link>
      </model>
      <model name='unit_box'>
        <pose frame=''>0.513161 0.000463 0.025 0 -0 0.068587</pose>
        <scale>1 1 1</scale>
        <link name='link'>
          <pose frame=''>0.513161 0.000463 0.025 0 -0 0.068587</pose>
          <velocity>0 0 0 0 -0 0</velocity>
          <acceleration>5.4e-05 -0.00018 10.0013 0.004991 0.001489 2e-05</acceleration>
          <wrench>5.4e-05 -0.00018 10.0013 0 -0 0</wrench>
        </link>
      </model>
      <model name='yumi'>
        <pose frame=''>0 0 0 0 -0 0</pose>
        <scale>1 1 1</scale>
        <link name='gripper_l_finger_l'>
          <pose frame=''>0.469401 0.294418 0.255469 1.86058 1.02327 1.85377</pose>
          <velocity>-0.001267 0.003948 -0.007275 -0.000587 0.000388 -3.6e-05</velocity>
          <acceleration>-1.26725 3.94848 -7.27493 -0.587212 0.387798 -0.036005</acceleration>
          <wrench>-0.05069 0.157939 -0.290997 0 -0 0</wrench>
        </link>
        <link name='gripper_l_finger_r'>
          <pose frame=''>0.462731 0.330662 0.219265 -1.8606 -1.02328 -1.2878</pose>
          <velocity>0.00017 -0.001034 0.001181 -0.000602 0.000812 0.000216</velocity>
          <acceleration>1.45987 -5.00736 8.56873 3.01583 0.768954 -1.70712</acceleration>
          <wrench>0.058395 -0.200294 0.342749 0 -0 0</wrench>
        </link>
        <link name='gripper_r_finger_l'>
          <pose frame=''>0.461018 -0.3166 0.257891 -1.93731 1.00359 -1.9484</pose>
          <velocity>-0.001753 -0.003964 -0.007048 0.000642 0.000806 -0.000322</velocity>
          <acceleration>-1.75279 -3.96355 -7.0479 0.642388 0.805689 -0.322075</acceleration>
          <wrench>-0.070111 -0.158542 -0.281916 0 -0 0</wrench>
        </link>
        <link name='gripper_r_finger_r'>
          <pose frame=''>0.450558 -0.330335 0.209205 1.93734 -1.00359 1.19316</pose>
          <velocity>-0.000104 0.000339 0.000159 0.000623 0.000971 -0.000413</velocity>
          <acceleration>-0.040463 -0.063189 -0.07532 -0.037066 -0.130904 0.020286</acceleration>
          <wrench>-0.001619 -0.002528 -0.003013 0 -0 0</wrench>
        </link>
        <link name='yumi_base_link'>
          <pose frame=''>0 0 0.1 0 -0 0</pose>
          <velocity>-3e-06 0 -6e-06 -6e-06 -3.2e-05 1e-06</velocity>
          <acceleration>-0.002832 0.001321 -0.006465 -0.023268 -0.03862 0.00117</acceleration>
          <wrench>-0.042474 0.019812 -0.096978 0 -0 0</wrench>
        </link>
        <link name='yumi_link_1_l'>
          <pose frame=''>0.05355 0.072499 0.514919 0.923866 0.677025 1.52662</pose>
          <velocity>-2.1e-05 4e-06 -6e-06 -0.000263 -0.000147 -0.000137</velocity>
          <acceleration>-0.028562 0.022432 -0.006464 -0.047539 -0.047698 0.012322</acceleration>
          <wrench>-0.057124 0.044864 -0.012929 0 -0 0</wrench>
        </link>
        <link name='yumi_link_1_r'>
          <pose frame=''>0.05355 -0.0725 0.51492 -0.938948 0.650974 -1.55132</pose>
          <velocity>-1.8e-05 3e-06 -2e-06 -2.7e-05 -3.3e-05 -1.2e-05</velocity>
          <acceleration>-0.02569 0.015025 0.005454 -0.0314 -0.05083 0.001241</acceleration>
          <wrench>-0.051379 0.03005 0.010907 0 -0 0</wrench>
        </link>
        <link name='yumi_link_2_l'>
          <pose frame=''>0.135967 0.130059 0.543105 -2.24343 0.059743 -2.35489</pose>
          <velocity>-1.7e-05 1e-06 -1e-05 -0.000475 4.8e-05 9e-05</velocity>
          <acceleration>-0.028641 0.022845 -0.011587 -0.050335 -0.040111 0.017026</acceleration>
          <wrench>-0.057281 0.04569 -0.023174 0 -0 0</wrench>
        </link>
        <link name='yumi_link_2_r'>
          <pose frame=''>0.135391 -0.130572 0.543725 -0.872049 0.064717 2.33606</pose>
          <velocity>-2.1e-05 3e-06 2e-06 0.000229 0.000184 -0.000294</velocity>
          <acceleration>-0.025692 0.014962 0.00629 -0.032984 -0.052934 -0.001745</acceleration>
          <wrench>-0.051384 0.029924 0.01258 0 -0 0</wrench>
        </link>
        <link name='yumi_link_3_l'>
          <pose frame=''>0.086573 0.233021 0.409954 2.57211 -0.384209 -2.95936</pose>
          <velocity>-3.3e-05 -6.6e-05 -5.7e-05 -0.000598 0.000193 -0.000143</velocity>
          <acceleration>-0.023245 0.017899 -0.020157 -0.051783 -0.031864 0.02181</acceleration>
          <wrench>-0.04649 0.035798 -0.040315 0 -0 0</wrench>
        </link>
        <link name='yumi_link_3_r'>
          <pose frame=''>0.081878 -0.235348 0.413616 -2.54943 -0.400588 2.93824</pose>
          <velocity>-7.7e-05 4.9e-05 -1.2e-05 0.000397 0.000369 2e-06</velocity>
          <acceleration>-0.021415 0.012287 0.007657 -0.034606 -0.053501 -0.006433</acceleration>
          <wrench>-0.042829 0.024574 0.015314 0 -0 0</wrench>
        </link>
        <link name='yumi_link_4_l'>
          <pose frame=''>0.092623 0.277302 0.332785 -2.82713 1.0173 1.8827</pose>
          <velocity>-4.1e-05 -0.000112 -8.5e-05 -0.000589 0.000378 -3.6e-05</velocity>
          <acceleration>-0.02065 0.014936 -0.023 -0.052659 -0.025443 0.02534</acceleration>
          <wrench>-0.041299 0.029871 -0.046001 0 -0 0</wrench>
        </link>
        <link name='yumi_link_4_r'>
          <pose frame=''>0.085824 -0.28103 0.33713 -0.32982 0.996494 -1.90476</pose>
          <velocity>-0.000106 7.9e-05 -3.2e-05 0.000383 0.000645 -0.000166</velocity>
          <acceleration>-0.018911 0.010385 0.009964 -0.036751 -0.058328 -0.007036</acceleration>
          <wrench>-0.037822 0.020771 0.019929 0 -0 0</wrench>
        </link>
        <link name='yumi_link_5_l'>
          <pose frame=''>0.248367 0.304377 0.271568 1.88675 1.02012 1.88445</pose>
          <velocity>-6.3e-05 -0.000154 -0.00016 -0.000605 0.000378 -3.3e-05</velocity>
          <acceleration>-0.019023 0.015633 -0.020103 -0.05304 -0.022638 0.026975</acceleration>
          <wrench>-0.038047 0.031266 -0.040206 0 -0 0</wrench>
        </link>
        <link name='yumi_link_5_r'>
          <pose frame=''>0.240417 -0.310579 0.274164 -1.90308 1.0011 -1.90769</pose>
          <velocity>-0.000152 7.8e-05 -0.000143 0.000557 0.000632 -0.000195</velocity>
          <acceleration>-0.01628 0.007607 0.021015 -0.038273 -0.064828 -0.006045</acceleration>
          <wrench>-0.032561 0.015214 0.04203 0 -0 0</wrench>
        </link>
        <link name='yumi_link_6_l'>
          <pose frame=''>0.351692 0.295094 0.278254 -2.851 1.02496 1.85474</pose>
          <velocity>-6.1e-05 -0.000153 -0.000193 -0.000605 0.000388 -2.8e-05</velocity>
          <acceleration>-0.019062 0.018804 -0.017472 -0.053146 -0.021804 0.027472</acceleration>
          <wrench>-0.038123 0.037608 -0.034944 0 -0 0</wrench>
        </link>
        <link name='yumi_link_6_r'>
          <pose frame=''>0.34391 -0.302178 0.279237 -0.361055 0.99439 -1.94193</pose>
          <velocity>-0.000147 5.5e-05 -0.000203 0.000548 0.000816 -0.000306</velocity>
          <acceleration>-0.017153 0.007587 0.028253 -0.039879 -0.06896 -0.005794</acceleration>
          <wrench>-0.034305 0.015174 0.056506 0 -0 0</wrench>
        </link>
        <link name='yumi_link_7_l'>
          <pose frame=''>0.376427 0.309515 0.250865 1.86057 1.02328 1.85377</pose>
          <velocity>-7.1e-05 -0.000171 -0.000211 -0.000587 0.000388 -3e-05</velocity>
          <acceleration>-0.018745 0.018069 -0.017631 -0.052793 -0.021069 0.027777</acceleration>
          <wrench>-0.041239 0.039753 -0.038787 0 -0 0</wrench>
        </link>
        <link name='yumi_link_7_r'>
          <pose frame=''>0.366971 -0.317726 0.251015 -1.93729 1.00359 -1.9484</pose>
          <velocity>-0.000175 6.4e-05 -0.000231 0.000642 0.000808 -0.000324</velocity>
          <acceleration>-0.015684 0.006539 0.031062 -0.040882 -0.070951 -0.006182</acceleration>
          <wrench>-0.034505 0.014387 0.068336 0 -0 0</wrench>
        </link>
      </model>
      <light name='sun'>
        <pose frame=''>0 0 10 0 -0 0</pose>
      </light>
    </state>
    <gui fullscreen='0'>
      <camera name='user_camera'>
        <pose frame=''>2.64326 -2.48332 0.58702 0 0.275643 2.35619</pose>
        <view_controller>orbit</view_controller>
        <projection_type>perspective</projection_type>
      </camera>
    </gui>
  </world>
</sdf>
